<?xml version="1.0"?>
<robot name="serbot">
  <link name="base_footprint"/>

  <joint name="base_joint" type="fixed">
    <parent link="base_footprint"/>
    <child link="base_link" />
    <origin xyz="0 0 0" rpy="0 0 0"/>
  </joint>

  <link name="base_link">
    <visual>
      <origin xyz="0 0 0" rpy="0 0 0"/>
      <geometry>
        <mesh filename="package://serbot_description/meshes/whole/TANK.stl" scale="0.1 0.1 0.1"/>
      </geometry>
      <material name="light_black"/>
    </visual>
  </link>

  <joint name="wheel_left_joint" type="continuous">
    <parent link="base_link"/>
    <child link="wheel_left_link"/>
    <origin xyz="0.0 0.3 0.05" rpy="-1.57 0 0"/>
    <axis xyz="0 0 1"/>
  </joint>
  <link name="wheel_left_link">
    <origin xyz="0 0 0" rpy="1.57 0 0"/>
  </link>

  <joint name="wheel_right_joint" type="continuous">
    <parent link="base_link"/>
    <child link="wheel_right_link"/>
    <origin xyz="0.0 -0.3 0.05" rpy="-1.57 0 0"/>
    <axis xyz="0 0 1"/>
  </joint>
  <link name="wheel_right_link">
    <origin xyz="0 0 0" rpy="1.57 0 0"/>
  </link>

  <joint name="scan_joint" type="fixed">
    <parent link="base_link"/>
    <child link="base_scan"/>
    <origin xyz="0 0 0.15" rpy="0 0 0"/>
  </joint>

  <link name="base_scan">
    <origin xyz="0 0 0" rpy="0 0 0"/>
  </link>
</robot>
